# -*- coding: utf-8 -*-
"""
Created on Tue Nov 27 20:40:09 2018

@author: vedant2
"""

<mujoco model="SASA">
    <compiler angle="degree" coordinate="local" inertiafromgeom="true"/>
    <custom>
    <numeric data="0.0 0.0 0.55 1.0 0.0 0.0 0.0 0.0 1.0 0.0 -1.0 0.0 -1.0 0.0 1.0" name="init_qpos"/>
    </custom>
    <option gravity="0 0 0" integrator="RK4" timestep="1e-4" />
    <worldbody>
        <body name="satellite" pos="0 0 0.0">
            <joint axis="1 0 0" damping="0.0" name="BASE_DOF" pos="0 0 0" type="free"/>
            <geom mass="500.0" pos="0 0 0" rgba="0 0 1 1" size="2 2.3 3" quat="0.707 0 0.707 0" type="box"/>
			<camera euler="0 0 0" fovy="60" name="rgb" pos="0 0 5.5"></camera>
		
        
            <body name="panelL0" pos="-5 0 0.0">
                <joint axis="1 0 0" stiffness="100" damping="0.0" name="panelL0_rotate_x" pos="1.5 0 0" type="hinge"/>
                <joint axis="0 1 0" stiffness="100" damping="0.0" name="panelL0_rotate_y" pos="1.5 0 0" type="hinge"/>
                <joint axis="0 0 1" stiffness="100" damping="0.0" name="panelL0_rotate_z" pos="1.5 0 0" type="hinge"/>
                <geom mass="20.0" rgba="0 1 0 1" size="2 0.15 3" type="box"/>
                
                <body name="panelL1" pos="-5 0 0.0">
                <joint axis="1 0 0" stiffness="100" damping="0.0" name="panelL1_rotate_x" pos="1.5 0 0" type="hinge"/>
                <joint axis="0 1 0" stiffness="100" damping="0.0" name="panelL1_rotate_y" pos="1.5 0 0" type="hinge"/>
                <joint axis="0 0 1" stiffness="100" damping="0.0" name="panelL1_rotate_z" pos="1.5 0 0" type="hinge"/>
                <geom mass="20.0" rgba="0 1 0 1" size="2 0.15 3" type="box"/>
            </body>
                
            </body>
            <body name="panelR0" pos="5 0 0.0">
                <joint axis="1 0 0" stiffness="100" damping="0.0" name="panelR0_rotate_x" pos="-1.5 0 0" type="hinge"/>
                <joint axis="0 1 0" stiffness="100" damping="0.0" name="panelR0_rotate_y" pos="-1.5 0 0" type="hinge"/>
                <joint axis="0 0 1" stiffness="100" damping="0.0" name="panelR0_rotate_z" pos="-1.5 0 0" type="hinge"/>
                <geom mass="20.0" rgba="1 0 0 1" size="2 0.15 3" type="box"/>
            
            <body name="panelR1" pos="5 0 0.0">
                <joint axis="1 0 0" stiffness="100" damping="0.0" name="panelR1_rotate_x" pos="-1.5 0 0" type="hinge"/>
                <joint axis="0 1 0" stiffness="100" damping="0.0" name="panelR1_rotate_y" pos="-1.5 0 0" type="hinge"/>
                <joint axis="0 0 1" stiffness="100" damping="0.0" name="panelR1_rotate_z" pos="-1.5 0 0" type="hinge"/>
                <geom mass="20.0" rgba="1 0 0 1" size="2 0.15 3" type="box"/>
            </body>
            
            </body>
        </body>
    </worldbody>
    <actuator>
    
        <motor gear="1 0 0 0 0 0 " joint="BASE_DOF"/>
        <motor gear="0 1 0 0 0 0 " joint="BASE_DOF"/>
        <motor gear="0 0 1 0 0 0 " joint="BASE_DOF"/>
        
        <motor gear="0 0 0 1 0 0 " joint="BASE_DOF"/>
        <motor gear="0 0 0 0 1 0 " joint="BASE_DOF"/>
        <motor gear="0 0 0 0 0 1 " joint="BASE_DOF"/>
        
        <motor gear="10000 " joint="panelL0_rotate_x"/>
        <motor gear="10000 " joint="panelL0_rotate_y"/>
        <motor gear="10000 " joint="panelL0_rotate_z"/>
        
        <motor gear="10000 " joint="panelL1_rotate_x"/>
        <motor gear="10000 " joint="panelL1_rotate_y"/>
        <motor gear="10000 " joint="panelL1_rotate_z"/>
        
        <motor gear="10000 " joint="panelR0_rotate_x"/>
        <motor gear="10000 " joint="panelR0_rotate_y"/>
        <motor gear="10000 " joint="panelR0_rotate_z"/>
        
        <motor gear="10000 " joint="panelR1_rotate_x"/>
        <motor gear="10000 " joint="panelR1_rotate_y"/>
        <motor gear="10000 " joint="panelR1_rotate_z"/>
        
    </actuator>
</mujoco>